Workbook

Sheet Resumo Executivo
A1: JourneyGraph MNO na Claro — Plano de Implementação
A2: Fases independentes e complementares, priorizadas por custo × benefício. Squads sênior — Brintell (novo, camada de análise/dashboards) + alocação parcial de recursos já existentes da CDRVIEW (Rafael, Feijão, Andréia, CS).
A4: Ordem | B4: Fase | C4: Entregável | D4: Sprints | E4: Semanas | F4: Benefício | G4: Custo relativo | H4: Custo total (R$)
A5: 1 | B5: Fase 1 — Personas & Qualidade de Deslocamento | C5: Segmentação real (K-Means+XGBoost), IPED e Vamping para Marketing/CRM, 1 região piloto, sobre tensor longitudinal que a GUI Análises do CDRVIEW já sabe exportar. | D5: 4 | E5: 8 | F5: Alto | G5: Médio | H5: ='Custo Detalhado'!G12
A6: 2 | B6: Fase 2 — Dashboard da Alarmística existente | C6: NOC passa a enxergar, numa interface nova, os alarmes que a Alarmística (7 VMs) já gera hoje — sem motor analítico novo, só exposição. | D6: 2 | E6: 4 | F6: Alto | G6: Baixo | H6: ='Custo Detalhado'!G18
A7: 3 | B7: Fase 3 — Analytics novo sobre a Alarmística | C7: Markov (tendência), Bayes ingênuo (causa provável) e MAD/Kalman (outlier) como consumidores read-only do stream de KQI já existente. | D7: 3 | E7: 6 | F7: Alto | G7: Médio | H7: ='Custo Detalhado'!G26
A8: 4 | B8: Fase 4 — Topologia de rede + Priorização de alertas | C8: SPOF, blast radius, centralidade e score combinado (gravidade × impacto de negócio), cruzando com o inventário/OSS real da rede. | D8: 4 | E8: 8 | F8: Alto | G8: Médio-Alto | H8: ='Custo Detalhado'!G36
A9: 5 | B9: Fase 5 — Streaming incremental completo (MLOps) | C9: Scoring de persona online, Markov/IPED/Vamping incrementais — o sistema deixa de ser um relatório recalculado e passa a ser vivo. | D9: 6 | E9: 12 | F9: Muito alto | G9: Alto | H9: ='Custo Detalhado'!G47
A10: 6 | B10: Fase 6 — Rollout nacional | C10: Extensão do particionamento validado no piloto para todas as regiões — majoritariamente operacional (CS), pouca engenharia nova. | D10: 6 | E10: 12 | F10: Muito alto | G10: Alto (mas operacional) | H10: ='Custo Detalhado'!G56
A11: TOTAL | H11: ='Custo Detalhado'!G58
A13: Notas de priorização
A14: • Fases 1 e 2 são as de melhor razão custo×benefício — nenhuma depende de integração nova de sistema, e reaproveitam a exportação de tensores e o motor de alarme que a CDRVIEW já tem em produção.
A15: • Fase 2 roda em paralelo à Fase 1 (equipes quase sem sobreposição) sem custo adicional de calendário.
A16: • Fases 3 e 4 poderiam rodar em paralelo se um segundo Cientista de Dados Sênior for contratado (~R$28.000/mês adicional) — comprime o cronograma em ~4 sprints (8 semanas). Ver aba Cronograma.
A17: • Fase 5 (streaming/MLOps) é a mais cara e só compensa depois que as Fases 1, 3 e 4 já provaram valor em lote — evita re-trabalho de engenharia num modelo analítico ainda não validado pelo negócio.
A18: • Custos de Rafael/Feijão/Andréia/CS são estimativas de alocação interna (custo de oportunidade), não gasto novo — mostrados para visibilidade total do custo do projeto, a validar com a Claro.

Sheet Papéis
A1: Papéis do projeto e custo mensal (sênior, alocação 100%)
A3: Papel | B3: Organização | C3: Natureza do custo | D3: Custo mensal (R$) | E3: Observação
A4: PM / Coordenação geral | B4: Vísent | C4: Novo (contratado) | D4: 30000 | E4: Coordenação ponta a ponta entre Brintell, CDRVIEW e CS.
A5: Arquiteto de Dados/Soluções Sênior | B5: Brintell | C5: Novo (contratado) | D5: 33000 | E5: Desenho de arquitetura, integração com os 4 tiers do CDRVIEW.
A6: Engenheiro de Dados Sênior — Pipelines/Tensores | B6: Brintell | C6: Novo (contratado) | D6: 27000 | E6: Consome tensores 3D/4D já exportáveis pela GUI Análises do CDRVIEW.
A7: Cientista de Dados Sênior — ML/Personas/Markov/Bayes | B7: Brintell | C7: Novo (contratado) | D7: 28000 | E7: K-Means/XGBoost, IPED, Vamping, Markov, Bayes ingênuo.
A8: Engenheiro de Software Sênior — Dashboards/API | B8: Brintell | C8: Novo (contratado) | D8: 25000 | E8: Frontend consumidor de API (substitui o padrão de blob estático da PoC).
A9: Engenheiro de Dados Sênior — MLOps/Streaming | B9: Brintell | C9: Novo (contratado) | D9: 27000 | E9: Incremental/online: scoring, Markov, IPED/Vamping incrementais (Fase 5).
A10: Rafael — Eng. CDRVIEW Sênior (Parser/Ingestão/Redução/API) | B10: Claro/CDRVIEW | C10: Alocação interna (custo de oportunidade) | D10: 28000 | E10: Estimativa para dimensionar o projeto — não é gasto novo, é tempo já custeado pela Claro.
A11: Feijão — Eng. CDRVIEW Sênior (Alarmística online/API) | B11: Claro/CDRVIEW | C11: Alocação interna (custo de oportunidade) | D11: 28000 | E11: Idem — estimativa de custo interno para visibilidade total do projeto.
A12: Andréia — QA Sênior | B12: Claro/CDRVIEW | C12: Alocação interna (custo de oportunidade) | D12: 18000 | E12: Idem.
A13: CS — Implantação/Rollout | B13: Claro | C13: Alocação interna (custo de oportunidade) | D13: 20000 | E13: Idem — líder de implantação, treinamento e go-live.

Sheet Custo Detalhado
A1: Custo detalhado por fase × papel (fórmulas — ajuste taxas na aba Papéis)
A3: Fase | B3: Papel | C3: Sprints | D3: Duração (meses) | E3: Alocação (%) | F3: Custo mensal (R$) | G3: Custo da linha (R$) | H3: Organização
A4: Fase 1 — Personas & Qualidade de Deslocamento | B4: PM / Coordenação geral | C4: 4 | D4: =C4*0.5 | E4: 0.5 | F4: =Papéis!D4 | G4: =D4*E4*F4 | H4: =Papéis!B4
A5: Fase 1 — Personas & Qualidade de Deslocamento | B5: Arquiteto de Dados/Soluções Sênior | C5: 4 | D5: =C5*0.5 | E5: 0.5 | F5: =Papéis!D5 | G5: =D5*E5*F5 | H5: =Papéis!B5
A6: Fase 1 — Personas & Qualidade de Deslocamento | B6: Engenheiro de Dados Sênior — Pipelines/Tensores | C6: 4 | D6: =C6*0.5 | E6: 1 | F6: =Papéis!D6 | G6: =D6*E6*F6 | H6: =Papéis!B6
A7: Fase 1 — Personas & Qualidade de Deslocamento | B7: Cientista de Dados Sênior — ML/Personas/Markov/Bayes | C7: 4 | D7: =C7*0.5 | E7: 1 | F7: =Papéis!D7 | G7: =D7*E7*F7 | H7: =Papéis!B7
A8: Fase 1 — Personas & Qualidade de Deslocamento | B8: Engenheiro de Software Sênior — Dashboards/API | C8: 4 | D8: =C8*0.5 | E8: 0.5 | F8: =Papéis!D8 | G8: =D8*E8*F8 | H8: =Papéis!B8
A9: Fase 1 — Personas & Qualidade de Deslocamento | B9: Rafael — Eng. CDRVIEW Sênior (Parser/Ingestão/Redução/API) | C9: 4 | D9: =C9*0.5 | E9: 0.2 | F9: =Papéis!D10 | G9: =D9*E9*F9 | H9: =Papéis!B10
A10: Fase 1 — Personas & Qualidade de Deslocamento | B10: Andréia — QA Sênior | C10: 4 | D10: =C10*0.5 | E10: 0.3 | F10: =Papéis!D12 | G10: =D10*E10*F10 | H10: =Papéis!B12
A11: Fase 1 — Personas & Qualidade de Deslocamento | B11: CS — Implantação/Rollout | C11: 4 | D11: =C11*0.5 | E11: 0.1 | F11: =Papéis!D13 | G11: =D11*E11*F11 | H11: =Papéis!B13
A12: Subtotal — Fase 1 — Personas & Qualidade de Deslocamento | G12: =SUM(G4:G11)
A14: Fase 2 — Dashboard da Alarmística existente | B14: PM / Coordenação geral | C14: 2 | D14: =C14*0.5 | E14: 0.3 | F14: =Papéis!D4 | G14: =D14*E14*F14 | H14: =Papéis!B4
A15: Fase 2 — Dashboard da Alarmística existente | B15: Engenheiro de Software Sênior — Dashboards/API | C15: 2 | D15: =C15*0.5 | E15: 1 | F15: =Papéis!D8 | G15: =D15*E15*F15 | H15: =Papéis!B8
A16: Fase 2 — Dashboard da Alarmística existente | B16: Feijão — Eng. CDRVIEW Sênior (Alarmística online/API) | C16: 2 | D16: =C16*0.5 | E16: 0.3 | F16: =Papéis!D11 | G16: =D16*E16*F16 | H16: =Papéis!B11
A17: Fase 2 — Dashboard da Alarmística existente | B17: Andréia — QA Sênior | C17: 2 | D17: =C17*0.5 | E17: 0.3 | F17: =Papéis!D12 | G17: =D17*E17*F17 | H17: =Papéis!B12
A18: Subtotal — Fase 2 — Dashboard da Alarmística existente | G18: =SUM(G14:G17)
A20: Fase 3 — Analytics novo sobre a Alarmística | B20: PM / Coordenação geral | C20: 3 | D20: =C20*0.5 | E20: 0.3 | F20: =Papéis!D4 | G20: =D20*E20*F20 | H20: =Papéis!B4
A21: Fase 3 — Analytics novo sobre a Alarmística | B21: Arquiteto de Dados/Soluções Sênior | C21: 3 | D21: =C21*0.5 | E21: 0.1 | F21: =Papéis!D5 | G21: =D21*E21*F21 | H21: =Papéis!B5
A22: Fase 3 — Analytics novo sobre a Alarmística | B22: Cientista de Dados Sênior — ML/Personas/Markov/Bayes | C22: 3 | D22: =C22*0.5 | E22: 1 | F22: =Papéis!D7 | G22: =D22*E22*F22 | H22: =Papéis!B7
A23: Fase 3 — Analytics novo sobre a Alarmística | B23: Engenheiro de Software Sênior — Dashboards/API | C23: 3 | D23: =C23*0.5 | E23: 0.5 | F23: =Papéis!D8 | G23: =D23*E23*F23 | H23: =Papéis!B8
A24: Fase 3 — Analytics novo sobre a Alarmística | B24: Feijão — Eng. CDRVIEW Sênior (Alarmística online/API) | C24: 3 | D24: =C24*0.5 | E24: 0.3 | F24: =Papéis!D11 | G24: =D24*E24*F24 | H24: =Papéis!B11
A25: Fase 3 — Analytics novo sobre a Alarmística | B25: Andréia — QA Sênior | C25: 3 | D25: =C25*0.5 | E25: 0.3 | F25: =Papéis!D12 | G25: =D25*E25*F25 | H25: =Papéis!B12
A26: Subtotal — Fase 3 — Analytics novo sobre a Alarmística | G26: =SUM(G20:G25)
A28: Fase 4 — Topologia de rede + Priorização de alertas | B28: PM / Coordenação geral | C28: 4 | D28: =C28*0.5 | E28: 0.4 | F28: =Papéis!D4 | G28: =D28*E28*F28 | H28: =Papéis!B4
A29: Fase 4 — Topologia de rede + Priorização de alertas | B29: Arquiteto de Dados/Soluções Sênior | C29: 4 | D29: =C29*0.5 | E29: 0.3 | F29: =Papéis!D5 | G29: =D29*E29*F29 | H29: =Papéis!B5
A30: Fase 4 — Topologia de rede + Priorização de alertas | B30: Engenheiro de Dados Sênior — Pipelines/Tensores | C30: 4 | D30: =C30*0.5 | E30: 0.8 | F30: =Papéis!D6 | G30: =D30*E30*F30 | H30: =Papéis!B6
A31: Fase 4 — Topologia de rede + Priorização de alertas | B31: Cientista de Dados Sênior — ML/Personas/Markov/Bayes | C31: 4 | D31: =C31*0.5 | E31: 0.6 | F31: =Papéis!D7 | G31: =D31*E31*F31 | H31: =Papéis!B7
A32: Fase 4 — Topologia de rede + Priorização de alertas | B32: Engenheiro de Software Sênior — Dashboards/API | C32: 4 | D32: =C32*0.5 | E32: 0.6 | F32: =Papéis!D8 | G32: =D32*E32*F32 | H32: =Papéis!B8
A33: Fase 4 — Topologia de rede + Priorização de alertas | B33: Rafael — Eng. CDRVIEW Sênior (Parser/Ingestão/Redução/API) | C33: 4 | D33: =C33*0.5 | E33: 0.3 | F33: =Papéis!D10 | G33: =D33*E33*F33 | H33: =Papéis!B10
A34: Fase 4 — Topologia de rede + Priorização de alertas | B34: Andréia — QA Sênior | C34: 4 | D34: =C34*0.5 | E34: 0.4 | F34: =Papéis!D12 | G34: =D34*E34*F34 | H34: =Papéis!B12
A35: Fase 4 — Topologia de rede + Priorização de alertas | B35: CS — Implantação/Rollout | C35: 4 | D35: =C35*0.5 | E35: 0.2 | F35: =Papéis!D13 | G35: =D35*E35*F35 | H35: =Papéis!B13
A36: Subtotal — Fase 4 — Topologia de rede + Priorização de alertas | G36: =SUM(G28:G35)
A38: Fase 5 — Streaming incremental completo (MLOps) | B38: PM / Coordenação geral | C38: 6 | D38: =C38*0.5 | E38: 0.5 | F38: =Papéis!D4 | G38: =D38*E38*F38 | H38: =Papéis!B4
A39: Fase 5 — Streaming incremental completo (MLOps) | B39: Arquiteto de Dados/Soluções Sênior | C39: 6 | D39: =C39*0.5 | E39: 0.5 | F39: =Papéis!D5 | G39: =D39*E39*F39 | H39: =Papéis!B5
A40: Fase 5 — Streaming incremental completo (MLOps) | B40: Cientista de Dados Sênior — ML/Personas/Markov/Bayes | C40: 6 | D40: =C40*0.5 | E40: 0.6 | F40: =Papéis!D7 | G40: =D40*E40*F40 | H40: =Papéis!B7
A41: Fase 5 — Streaming incremental completo (MLOps) | B41: Engenheiro de Software Sênior — Dashboards/API | C41: 6 | D41: =C41*0.5 | E41: 0.5 | F41: =Papéis!D8 | G41: =D41*E41*F41 | H41: =Papéis!B8
A42: Fase 5 — Streaming incremental completo (MLOps) | B42: Engenheiro de Dados Sênior — MLOps/Streaming | C42: 6 | D42: =C42*0.5 | E42: 1 | F42: =Papéis!D9 | G42: =D42*E42*F42 | H42: =Papéis!B9
A43: Fase 5 — Streaming incremental completo (MLOps) | B43: Rafael — Eng. CDRVIEW Sênior (Parser/Ingestão/Redução/API) | C43: 6 | D43: =C43*0.5 | E43: 0.4 | F43: =Papéis!D10 | G43: =D43*E43*F43 | H43: =Papéis!B10
A44: Fase 5 — Streaming incremental completo (MLOps) | B44: Feijão — Eng. CDRVIEW Sênior (Alarmística online/API) | C44: 6 | D44: =C44*0.5 | E44: 0.4 | F44: =Papéis!D11 | G44: =D44*E44*F44 | H44: =Papéis!B11
A45: Fase 5 — Streaming incremental completo (MLOps) | B45: Andréia — QA Sênior | C45: 6 | D45: =C45*0.5 | E45: 0.5 | F45: =Papéis!D12 | G45: =D45*E45*F45 | H45: =Papéis!B12
...

Sheet Cronograma
A1: Cronograma — sprints de 2 semanas (plano enxuto, 1 FTE por papel)
A3: Fase | B3: Início | C3: Fim | D3: S1 | E3: S2 | F3: S3 | G3: S4 | H3: S5 | I3: S6 | J3: S7 | K3: S8 | L3: S9 | M3: S10 | N3: S11 | O3: S12 | P3: S13 | Q3: S14 | R3: S15 | S3: S16 | T3: S17 | U3: S18 | V3: S19 | W3: S20 | X3: S21 | Y3: S22 | Z3: S23
A4: Fase 1 — Personas & Qualidade de Deslocamento | B4: Sprint 1 | C4: Sprint 4
A5: Fase 2 — Dashboard da Alarmística existente | B5: Sprint 1 | C5: Sprint 2
A6: Fase 3 — Analytics novo sobre a Alarmística | B6: Sprint 5 | C6: Sprint 7
A7: Fase 4 — Topologia de rede + Priorização de alertas | B7: Sprint 8 | C7: Sprint 11
A8: Fase 5 — Streaming incremental completo (MLOps) | B8: Sprint 12 | C8: Sprint 17
A9: Fase 6 — Rollout nacional | B9: Sprint 18 | C9: Sprint 23
A11: Cronograma sequencial-enxuto (1 pessoa por papel). Compressão possível adicionando FTE — ver Resumo Executivo.

Sheet Matriz de Recursos
A1: Matriz de recursos — % de alocação por papel e por fase
A3: Papel | B3: Organização | C3: Fase 1 | D3: Fase 2 | E3: Fase 3 | F3: Fase 4 | G3: Fase 5 | H3: Fase 6
A4: PM / Coordenação geral | B4: Vísent | C4: 0.5 | D4: 0.3 | E4: 0.3 | F4: 0.4 | G4: 0.5 | H4: 0.4
A5: Arquiteto de Dados/Soluções Sênior | B5: Brintell | C5: 0.5 | E5: 0.1 | F5: 0.3 | G5: 0.5
A6: Engenheiro de Dados Sênior — Pipelines/Tensores | B6: Brintell | C6: 1 | F6: 0.8 | H6: 0.3
A7: Cientista de Dados Sênior — ML/Personas/Markov/Bayes | B7: Brintell | C7: 1 | E7: 1 | F7: 0.6 | G7: 0.6
A8: Engenheiro de Software Sênior — Dashboards/API | B8: Brintell | C8: 0.5 | D8: 1 | E8: 0.5 | F8: 0.6 | G8: 0.5 | H8: 0.2
A9: Engenheiro de Dados Sênior — MLOps/Streaming | B9: Brintell | G9: 1
A10: Rafael — Eng. CDRVIEW Sênior (Parser/Ingestão/Redução/API) | B10: Claro/CDRVIEW | C10: 0.2 | F10: 0.3 | G10: 0.4 | H10: 0.2
A11: Feijão — Eng. CDRVIEW Sênior (Alarmística online/API) | B11: Claro/CDRVIEW | D11: 0.3 | E11: 0.3 | G11: 0.4 | H11: 0.2
A12: Andréia — QA Sênior | B12: Claro/CDRVIEW | C12: 0.3 | D12: 0.3 | E12: 0.3 | F12: 0.4 | G12: 0.5 | H12: 0.4
A13: CS — Implantação/Rollout | B13: Claro | C13: 0.1 | F13: 0.2 | G13: 0.2 | H13: 1
A15: Vermelho = alocação alta (≥80%) · Amarelo = média (40–79%) · Verde = pontual (<40%)

Sheet Custo Individual
A1: Custo individual — total de cada papel no projeto completo
A3: Papel | B3: Organização | C3: Custo mensal (R$) | D3: Meses no projeto (soma ponderada) | E3: Custo total no projeto (R$) | F3: % do total
A4: PM / Coordenação geral | B4: Vísent | C4: =Papéis!D4 | D4: =SUMPRODUCT(('Custo Detalhado'!$B$4:$B$200=A4)*'Custo Detalhado'!$D$4:$D$200*'Custo Detalhado'!$E$4:$E$200) | E4: =SUMIF('Custo Detalhado'!B:B,A4,'Custo Detalhado'!G:G) | F4: =E4/E14
A5: Arquiteto de Dados/Soluções Sênior | B5: Brintell | C5: =Papéis!D5 | D5: =SUMPRODUCT(('Custo Detalhado'!$B$4:$B$200=A5)*'Custo Detalhado'!$D$4:$D$200*'Custo Detalhado'!$E$4:$E$200) | E5: =SUMIF('Custo Detalhado'!B:B,A5,'Custo Detalhado'!G:G) | F5: =E5/E14
A6: Engenheiro de Dados Sênior — Pipelines/Tensores | B6: Brintell | C6: =Papéis!D6 | D6: =SUMPRODUCT(('Custo Detalhado'!$B$4:$B$200=A6)*'Custo Detalhado'!$D$4:$D$200*'Custo Detalhado'!$E$4:$E$200) | E6: =SUMIF('Custo Detalhado'!B:B,A6,'Custo Detalhado'!G:G) | F6: =E6/E14
A7: Cientista de Dados Sênior — ML/Personas/Markov/Bayes | B7: Brintell | C7: =Papéis!D7 | D7: =SUMPRODUCT(('Custo Detalhado'!$B$4:$B$200=A7)*'Custo Detalhado'!$D$4:$D$200*'Custo Detalhado'!$E$4:$E$200) | E7: =SUMIF('Custo Detalhado'!B:B,A7,'Custo Detalhado'!G:G) | F7: =E7/E14
A8: Engenheiro de Software Sênior — Dashboards/API | B8: Brintell | C8: =Papéis!D8 | D8: =SUMPRODUCT(('Custo Detalhado'!$B$4:$B$200=A8)*'Custo Detalhado'!$D$4:$D$200*'Custo Detalhado'!$E$4:$E$200) | E8: =SUMIF('Custo Detalhado'!B:B,A8,'Custo Detalhado'!G:G) | F8: =E8/E14
A9: Engenheiro de Dados Sênior — MLOps/Streaming | B9: Brintell | C9: =Papéis!D9 | D9: =SUMPRODUCT(('Custo Detalhado'!$B$4:$B$200=A9)*'Custo Detalhado'!$D$4:$D$200*'Custo Detalhado'!$E$4:$E$200) | E9: =SUMIF('Custo Detalhado'!B:B,A9,'Custo Detalhado'!G:G) | F9: =E9/E14
A10: Rafael — Eng. CDRVIEW Sênior (Parser/Ingestão/Redução/API) | B10: Claro/CDRVIEW | C10: =Papéis!D10 | D10: =SUMPRODUCT(('Custo Detalhado'!$B$4:$B$200=A10)*'Custo Detalhado'!$D$4:$D$200*'Custo Detalhado'!$E$4:$E$200) | E10: =SUMIF('Custo Detalhado'!B:B,A10,'Custo Detalhado'!G:G) | F10: =E10/E14
A11: Feijão — Eng. CDRVIEW Sênior (Alarmística online/API) | B11: Claro/CDRVIEW | C11: =Papéis!D11 | D11: =SUMPRODUCT(('Custo Detalhado'!$B$4:$B$200=A11)*'Custo Detalhado'!$D$4:$D$200*'Custo Detalhado'!$E$4:$E$200) | E11: =SUMIF('Custo Detalhado'!B:B,A11,'Custo Detalhado'!G:G) | F11: =E11/E14
A12: Andréia — QA Sênior | B12: Claro/CDRVIEW | C12: =Papéis!D12 | D12: =SUMPRODUCT(('Custo Detalhado'!$B$4:$B$200=A12)*'Custo Detalhado'!$D$4:$D$200*'Custo Detalhado'!$E$4:$E$200) | E12: =SUMIF('Custo Detalhado'!B:B,A12,'Custo Detalhado'!G:G) | F12: =E12/E14
A13: CS — Implantação/Rollout | B13: Claro | C13: =Papéis!D13 | D13: =SUMPRODUCT(('Custo Detalhado'!$B$4:$B$200=A13)*'Custo Detalhado'!$D$4:$D$200*'Custo Detalhado'!$E$4:$E$200) | E13: =SUMIF('Custo Detalhado'!B:B,A13,'Custo Detalhado'!G:G) | F13: =E13/E14
A14: TOTAL | E14: =SUM(E4:E13)
